2018-08-22 21:58:53,969 [Thread-2:4536] [django.request:228] [log:log_response] [ERROR]- Internal Server Error: /
Traceback (most recent call last):
  File "E:\Envs\newblog-ES3JapFS\lib\site-packages\django\core\handlers\exception.py", line 34, in inner
    response = get_response(request)
  File "E:\Envs\newblog-ES3JapFS\lib\site-packages\django\core\handlers\base.py", line 126, in _get_response
    response = self.process_exception_by_middleware(e, request)
  File "E:\Envs\newblog-ES3JapFS\lib\site-packages\django\core\handlers\base.py", line 124, in _get_response
    response = wrapped_callback(request, *callback_args, **callback_kwargs)
  File "E:\PycharmProjects\mywebsite\myweb\views.py", line 24, in main
    return render(request, 'main.html', locals())
  File "E:\Envs\newblog-ES3JapFS\lib\site-packages\django\shortcuts.py", line 36, in render
    content = loader.render_to_string(template_name, context, request, using=using)
  File "E:\Envs\newblog-ES3JapFS\lib\site-packages\django\template\loader.py", line 62, in render_to_string
    return template.render(context, request)
  File "E:\Envs\newblog-ES3JapFS\lib\site-packages\django\template\backends\django.py", line 61, in render
    return self.template.render(context)
  File "E:\Envs\newblog-ES3JapFS\lib\site-packages\django\template\base.py", line 171, in render
    return self._render(context)
  File "E:\Envs\newblog-ES3JapFS\lib\site-packages\django\template\base.py", line 163, in _render
    return self.nodelist.render(context)
  File "E:\Envs\newblog-ES3JapFS\lib\site-packages\django\template\base.py", line 937, in render
    bit = node.render_annotated(context)
  File "E:\Envs\newblog-ES3JapFS\lib\site-packages\django\template\base.py", line 904, in render_annotated
    return self.render(context)
  File "E:\Envs\newblog-ES3JapFS\lib\site-packages\django\template\loader_tags.py", line 150, in render
    return compiled_parent._render(context)
  File "E:\Envs\newblog-ES3JapFS\lib\site-packages\django\template\base.py", line 163, in _render
    return self.nodelist.render(context)
  File "E:\Envs\newblog-ES3JapFS\lib\site-packages\django\template\base.py", line 937, in render
    bit = node.render_annotated(context)
  File "E:\Envs\newblog-ES3JapFS\lib\site-packages\django\template\base.py", line 904, in render_annotated
    return self.render(context)
  File "E:\Envs\newblog-ES3JapFS\lib\site-packages\django\template\loader_tags.py", line 62, in render
    result = block.nodelist.render(context)
  File "E:\Envs\newblog-ES3JapFS\lib\site-packages\django\template\base.py", line 937, in render
    bit = node.render_annotated(context)
  File "E:\Envs\newblog-ES3JapFS\lib\site-packages\django\template\base.py", line 904, in render_annotated
    return self.render(context)
  File "E:\Envs\newblog-ES3JapFS\lib\site-packages\django\template\defaulttags.py", line 209, in render
    nodelist.append(node.render_annotated(context))
  File "E:\Envs\newblog-ES3JapFS\lib\site-packages\django\template\base.py", line 904, in render_annotated
    return self.render(context)
  File "E:\Envs\newblog-ES3JapFS\lib\site-packages\django\template\defaulttags.py", line 442, in render
    url = reverse(view_name, args=args, kwargs=kwargs, current_app=current_app)
  File "E:\Envs\newblog-ES3JapFS\lib\site-packages\django\urls\base.py", line 90, in reverse
    return iri_to_uri(resolver._reverse_with_prefix(view, prefix, *args, **kwargs))
  File "E:\Envs\newblog-ES3JapFS\lib\site-packages\django\urls\resolvers.py", line 622, in _reverse_with_prefix
    raise NoReverseMatch(msg)
django.urls.exceptions.NoReverseMatch: Reverse for 'article' not found. 'article' is not a valid view function or pattern name.
2018-08-22 22:17:23,650 [Thread-7:10412] [django.request:228] [log:log_response] [WARNING]- Not Found: /blog/add_article/
2018-08-22 22:17:27,202 [Thread-15:9496] [django.request:228] [log:log_response] [WARNING]- Not Found: /favicon.ico
2018-08-22 22:17:27,217 [Thread-16:8944] [django.request:228] [log:log_response] [WARNING]- Not Found: /favicon.ico
2018-08-22 22:58:05,759 [Thread-190:10228] [django.request:228] [log:log_response] [ERROR]- Internal Server Error: /article
Traceback (most recent call last):
  File "E:\Envs\newblog-ES3JapFS\lib\site-packages\django\core\handlers\exception.py", line 34, in inner
    response = get_response(request)
  File "E:\Envs\newblog-ES3JapFS\lib\site-packages\django\core\handlers\base.py", line 126, in _get_response
    response = self.process_exception_by_middleware(e, request)
  File "E:\Envs\newblog-ES3JapFS\lib\site-packages\django\core\handlers\base.py", line 124, in _get_response
    response = wrapped_callback(request, *callback_args, **callback_kwargs)
  File "E:\PycharmProjects\mywebsite\myweb\views.py", line 51, in article
    return render(request, 'article.html', locals())
  File "E:\Envs\newblog-ES3JapFS\lib\site-packages\django\shortcuts.py", line 36, in render
    content = loader.render_to_string(template_name, context, request, using=using)
  File "E:\Envs\newblog-ES3JapFS\lib\site-packages\django\template\loader.py", line 62, in render_to_string
    return template.render(context, request)
  File "E:\Envs\newblog-ES3JapFS\lib\site-packages\django\template\backends\django.py", line 61, in render
    return self.template.render(context)
  File "E:\Envs\newblog-ES3JapFS\lib\site-packages\django\template\base.py", line 171, in render
    return self._render(context)
  File "E:\Envs\newblog-ES3JapFS\lib\site-packages\django\template\base.py", line 163, in _render
    return self.nodelist.render(context)
  File "E:\Envs\newblog-ES3JapFS\lib\site-packages\django\template\base.py", line 937, in render
    bit = node.render_annotated(context)
  File "E:\Envs\newblog-ES3JapFS\lib\site-packages\django\template\base.py", line 904, in render_annotated
    return self.render(context)
  File "E:\Envs\newblog-ES3JapFS\lib\site-packages\django\template\loader_tags.py", line 150, in render
    return compiled_parent._render(context)
  File "E:\Envs\newblog-ES3JapFS\lib\site-packages\django\template\base.py", line 163, in _render
    return self.nodelist.render(context)
  File "E:\Envs\newblog-ES3JapFS\lib\site-packages\django\template\base.py", line 937, in render
    bit = node.render_annotated(context)
  File "E:\Envs\newblog-ES3JapFS\lib\site-packages\django\template\base.py", line 904, in render_annotated
    return self.render(context)
  File "E:\Envs\newblog-ES3JapFS\lib\site-packages\django\template\defaulttags.py", line 442, in render
    url = reverse(view_name, args=args, kwargs=kwargs, current_app=current_app)
  File "E:\Envs\newblog-ES3JapFS\lib\site-packages\django\urls\base.py", line 90, in reverse
    return iri_to_uri(resolver._reverse_with_prefix(view, prefix, *args, **kwargs))
  File "E:\Envs\newblog-ES3JapFS\lib\site-packages\django\urls\resolvers.py", line 622, in _reverse_with_prefix
    raise NoReverseMatch(msg)
django.urls.exceptions.NoReverseMatch: Reverse for '/' not found. '/' is not a valid view function or pattern name.
2018-08-22 23:01:12,762 [Thread-235:14756] [django.request:228] [log:log_response] [ERROR]- Internal Server Error: /article
Traceback (most recent call last):
  File "E:\Envs\newblog-ES3JapFS\lib\site-packages\django\core\handlers\exception.py", line 34, in inner
    response = get_response(request)
  File "E:\Envs\newblog-ES3JapFS\lib\site-packages\django\core\handlers\base.py", line 126, in _get_response
    response = self.process_exception_by_middleware(e, request)
  File "E:\Envs\newblog-ES3JapFS\lib\site-packages\django\core\handlers\base.py", line 124, in _get_response
    response = wrapped_callback(request, *callback_args, **callback_kwargs)
  File "E:\PycharmProjects\mywebsite\myweb\views.py", line 51, in article
    return render(request, 'article.html', locals())
  File "E:\Envs\newblog-ES3JapFS\lib\site-packages\django\shortcuts.py", line 36, in render
    content = loader.render_to_string(template_name, context, request, using=using)
  File "E:\Envs\newblog-ES3JapFS\lib\site-packages\django\template\loader.py", line 62, in render_to_string
    return template.render(context, request)
  File "E:\Envs\newblog-ES3JapFS\lib\site-packages\django\template\backends\django.py", line 61, in render
    return self.template.render(context)
  File "E:\Envs\newblog-ES3JapFS\lib\site-packages\django\template\base.py", line 171, in render
    return self._render(context)
  File "E:\Envs\newblog-ES3JapFS\lib\site-packages\django\template\base.py", line 163, in _render
    return self.nodelist.render(context)
  File "E:\Envs\newblog-ES3JapFS\lib\site-packages\django\template\base.py", line 937, in render
    bit = node.render_annotated(context)
  File "E:\Envs\newblog-ES3JapFS\lib\site-packages\django\template\base.py", line 904, in render_annotated
    return self.render(context)
  File "E:\Envs\newblog-ES3JapFS\lib\site-packages\django\template\loader_tags.py", line 150, in render
    return compiled_parent._render(context)
  File "E:\Envs\newblog-ES3JapFS\lib\site-packages\django\template\base.py", line 163, in _render
    return self.nodelist.render(context)
  File "E:\Envs\newblog-ES3JapFS\lib\site-packages\django\template\base.py", line 937, in render
    bit = node.render_annotated(context)
  File "E:\Envs\newblog-ES3JapFS\lib\site-packages\django\template\base.py", line 904, in render_annotated
    return self.render(context)
  File "E:\Envs\newblog-ES3JapFS\lib\site-packages\django\template\defaulttags.py", line 442, in render
    url = reverse(view_name, args=args, kwargs=kwargs, current_app=current_app)
  File "E:\Envs\newblog-ES3JapFS\lib\site-packages\django\urls\base.py", line 90, in reverse
    return iri_to_uri(resolver._reverse_with_prefix(view, prefix, *args, **kwargs))
  File "E:\Envs\newblog-ES3JapFS\lib\site-packages\django\urls\resolvers.py", line 622, in _reverse_with_prefix
    raise NoReverseMatch(msg)
django.urls.exceptions.NoReverseMatch: Reverse for 'add_article' not found. 'add_article' is not a valid view function or pattern name.
2018-08-23 00:03:50,106 [Thread-8:15120] [django.request:228] [log:log_response] [WARNING]- Not Found: /main.html
2018-08-23 00:30:33,634 [Thread-58:17360] [django.request:228] [log:log_response] [WARNING]- Not Found: /community.html
2018-08-23 00:31:18,115 [Thread-82:9888] [django.request:228] [log:log_response] [WARNING]- Not Found: /community.html
2018-08-23 00:31:52,908 [Thread-92:16592] [django.request:228] [log:log_response] [WARNING]- Not Found: /community.html
2018-08-23 00:32:29,851 [Thread-103:1600] [django.request:228] [log:log_response] [WARNING]- Not Found: /favicon.ico
2018-08-23 00:50:32,124 [Thread-16:9208] [django.request:228] [log:log_response] [ERROR]- Internal Server Error: /add_article
Traceback (most recent call last):
  File "E:\Envs\newblog-ES3JapFS\lib\site-packages\django\db\backends\utils.py", line 85, in _execute
    return self.cursor.execute(sql, params)
  File "E:\Envs\newblog-ES3JapFS\lib\site-packages\django\db\backends\mysql\base.py", line 71, in execute
    return self.cursor.execute(query, args)
  File "E:\Envs\newblog-ES3JapFS\lib\site-packages\pymysql\cursors.py", line 170, in execute
    result = self._query(query)
  File "E:\Envs\newblog-ES3JapFS\lib\site-packages\pymysql\cursors.py", line 328, in _query
    conn.query(q)
  File "E:\Envs\newblog-ES3JapFS\lib\site-packages\pymysql\connections.py", line 516, in query
    self._affected_rows = self._read_query_result(unbuffered=unbuffered)
  File "E:\Envs\newblog-ES3JapFS\lib\site-packages\pymysql\connections.py", line 727, in _read_query_result
    result.read()
  File "E:\Envs\newblog-ES3JapFS\lib\site-packages\pymysql\connections.py", line 1066, in read
    first_packet = self.connection._read_packet()
  File "E:\Envs\newblog-ES3JapFS\lib\site-packages\pymysql\connections.py", line 683, in _read_packet
    packet.check_error()
  File "E:\Envs\newblog-ES3JapFS\lib\site-packages\pymysql\protocol.py", line 220, in check_error
    err.raise_mysql_exception(self._data)
  File "E:\Envs\newblog-ES3JapFS\lib\site-packages\pymysql\err.py", line 109, in raise_mysql_exception
    raise errorclass(errno, errval)
pymysql.err.IntegrityError: (1048, "Column 'user_id' cannot be null")

The above exception was the direct cause of the following exception:

Traceback (most recent call last):
  File "E:\Envs\newblog-ES3JapFS\lib\site-packages\django\core\handlers\exception.py", line 34, in inner
    response = get_response(request)
  File "E:\Envs\newblog-ES3JapFS\lib\site-packages\django\core\handlers\base.py", line 126, in _get_response
    response = self.process_exception_by_middleware(e, request)
  File "E:\Envs\newblog-ES3JapFS\lib\site-packages\django\core\handlers\base.py", line 124, in _get_response
    response = wrapped_callback(request, *callback_args, **callback_kwargs)
  File "E:\PycharmProjects\mywebsite\myweb\views.py", line 58, in add_article
    add_article_form.save()
  File "E:\Envs\newblog-ES3JapFS\lib\site-packages\django\forms\models.py", line 458, in save
    self.instance.save()
  File "E:\Envs\newblog-ES3JapFS\lib\site-packages\django\db\models\base.py", line 717, in save
    force_update=force_update, update_fields=update_fields)
  File "E:\Envs\newblog-ES3JapFS\lib\site-packages\django\db\models\base.py", line 747, in save_base
    updated = self._save_table(raw, cls, force_insert, force_update, using, update_fields)
  File "E:\Envs\newblog-ES3JapFS\lib\site-packages\django\db\models\base.py", line 830, in _save_table
    result = self._do_insert(cls._base_manager, using, fields, update_pk, raw)
  File "E:\Envs\newblog-ES3JapFS\lib\site-packages\django\db\models\base.py", line 868, in _do_insert
    using=using, raw=raw)
  File "E:\Envs\newblog-ES3JapFS\lib\site-packages\django\db\models\manager.py", line 82, in manager_method
    return getattr(self.get_queryset(), name)(*args, **kwargs)
  File "E:\Envs\newblog-ES3JapFS\lib\site-packages\django\db\models\query.py", line 1133, in _insert
    return query.get_compiler(using=using).execute_sql(return_id)
  File "E:\Envs\newblog-ES3JapFS\lib\site-packages\django\db\models\sql\compiler.py", line 1285, in execute_sql
    cursor.execute(sql, params)
  File "E:\Envs\newblog-ES3JapFS\lib\site-packages\django\db\backends\utils.py", line 100, in execute
    return super().execute(sql, params)
  File "E:\Envs\newblog-ES3JapFS\lib\site-packages\django\db\backends\utils.py", line 68, in execute
    return self._execute_with_wrappers(sql, params, many=False, executor=self._execute)
  File "E:\Envs\newblog-ES3JapFS\lib\site-packages\django\db\backends\utils.py", line 77, in _execute_with_wrappers
    return executor(sql, params, many, context)
  File "E:\Envs\newblog-ES3JapFS\lib\site-packages\django\db\backends\utils.py", line 85, in _execute
    return self.cursor.execute(sql, params)
  File "E:\Envs\newblog-ES3JapFS\lib\site-packages\django\db\utils.py", line 89, in __exit__
    raise dj_exc_value.with_traceback(traceback) from exc_value
  File "E:\Envs\newblog-ES3JapFS\lib\site-packages\django\db\backends\utils.py", line 85, in _execute
    return self.cursor.execute(sql, params)
  File "E:\Envs\newblog-ES3JapFS\lib\site-packages\django\db\backends\mysql\base.py", line 71, in execute
    return self.cursor.execute(query, args)
  File "E:\Envs\newblog-ES3JapFS\lib\site-packages\pymysql\cursors.py", line 170, in execute
    result = self._query(query)
  File "E:\Envs\newblog-ES3JapFS\lib\site-packages\pymysql\cursors.py", line 328, in _query
    conn.query(q)
  File "E:\Envs\newblog-ES3JapFS\lib\site-packages\pymysql\connections.py", line 516, in query
    self._affected_rows = self._read_query_result(unbuffered=unbuffered)
  File "E:\Envs\newblog-ES3JapFS\lib\site-packages\pymysql\connections.py", line 727, in _read_query_result
    result.read()
  File "E:\Envs\newblog-ES3JapFS\lib\site-packages\pymysql\connections.py", line 1066, in read
    first_packet = self.connection._read_packet()
  File "E:\Envs\newblog-ES3JapFS\lib\site-packages\pymysql\connections.py", line 683, in _read_packet
    packet.check_error()
  File "E:\Envs\newblog-ES3JapFS\lib\site-packages\pymysql\protocol.py", line 220, in check_error
    err.raise_mysql_exception(self._data)
  File "E:\Envs\newblog-ES3JapFS\lib\site-packages\pymysql\err.py", line 109, in raise_mysql_exception
    raise errorclass(errno, errval)
django.db.utils.IntegrityError: (1048, "Column 'user_id' cannot be null")
2018-08-23 01:38:44,188 [Thread-2:8500] [django.request:228] [log:log_response] [ERROR]- Internal Server Error: /
Traceback (most recent call last):
  File "E:\Envs\newblog-ES3JapFS\lib\site-packages\django\core\handlers\exception.py", line 34, in inner
    response = get_response(request)
  File "E:\Envs\newblog-ES3JapFS\lib\site-packages\django\core\handlers\base.py", line 126, in _get_response
    response = self.process_exception_by_middleware(e, request)
  File "E:\Envs\newblog-ES3JapFS\lib\site-packages\django\core\handlers\base.py", line 124, in _get_response
    response = wrapped_callback(request, *callback_args, **callback_kwargs)
  File "E:\PycharmProjects\mywebsite\myweb\views.py", line 27, in main
    return render(request, 'main.html', locals())
  File "E:\Envs\newblog-ES3JapFS\lib\site-packages\django\shortcuts.py", line 36, in render
    content = loader.render_to_string(template_name, context, request, using=using)
  File "E:\Envs\newblog-ES3JapFS\lib\site-packages\django\template\loader.py", line 62, in render_to_string
    return template.render(context, request)
  File "E:\Envs\newblog-ES3JapFS\lib\site-packages\django\template\backends\django.py", line 61, in render
    return self.template.render(context)
  File "E:\Envs\newblog-ES3JapFS\lib\site-packages\django\template\base.py", line 171, in render
    return self._render(context)
  File "E:\Envs\newblog-ES3JapFS\lib\site-packages\django\template\base.py", line 163, in _render
    return self.nodelist.render(context)
  File "E:\Envs\newblog-ES3JapFS\lib\site-packages\django\template\base.py", line 937, in render
    bit = node.render_annotated(context)
  File "E:\Envs\newblog-ES3JapFS\lib\site-packages\django\template\base.py", line 904, in render_annotated
    return self.render(context)
  File "E:\Envs\newblog-ES3JapFS\lib\site-packages\django\template\loader_tags.py", line 150, in render
    return compiled_parent._render(context)
  File "E:\Envs\newblog-ES3JapFS\lib\site-packages\django\template\base.py", line 163, in _render
    return self.nodelist.render(context)
  File "E:\Envs\newblog-ES3JapFS\lib\site-packages\django\template\base.py", line 937, in render
    bit = node.render_annotated(context)
  File "E:\Envs\newblog-ES3JapFS\lib\site-packages\django\template\base.py", line 904, in render_annotated
    return self.render(context)
  File "E:\Envs\newblog-ES3JapFS\lib\site-packages\django\template\loader_tags.py", line 62, in render
    result = block.nodelist.render(context)
  File "E:\Envs\newblog-ES3JapFS\lib\site-packages\django\template\base.py", line 937, in render
    bit = node.render_annotated(context)
  File "E:\Envs\newblog-ES3JapFS\lib\site-packages\django\template\base.py", line 904, in render_annotated
    return self.render(context)
  File "E:\Envs\newblog-ES3JapFS\lib\site-packages\django\template\defaulttags.py", line 209, in render
    nodelist.append(node.render_annotated(context))
  File "E:\Envs\newblog-ES3JapFS\lib\site-packages\django\template\base.py", line 904, in render_annotated
    return self.render(context)
  File "E:\Envs\newblog-ES3JapFS\lib\site-packages\django\template\defaulttags.py", line 442, in render
    url = reverse(view_name, args=args, kwargs=kwargs, current_app=current_app)
  File "E:\Envs\newblog-ES3JapFS\lib\site-packages\django\urls\base.py", line 90, in reverse
    return iri_to_uri(resolver._reverse_with_prefix(view, prefix, *args, **kwargs))
  File "E:\Envs\newblog-ES3JapFS\lib\site-packages\django\urls\resolvers.py", line 622, in _reverse_with_prefix
    raise NoReverseMatch(msg)
django.urls.exceptions.NoReverseMatch: Reverse for 'article' with no arguments not found. 1 pattern(s) tried: ['article\\/\\(\\?p(?P<pk>[^/]+)\\[0\\-9\\]\\+\\)$']
2018-08-23 01:39:51,081 [Thread-3:17012] [django.request:228] [log:log_response] [ERROR]- Internal Server Error: /add_article
Traceback (most recent call last):
  File "E:\Envs\newblog-ES3JapFS\lib\site-packages\django\core\handlers\exception.py", line 34, in inner
    response = get_response(request)
  File "E:\Envs\newblog-ES3JapFS\lib\site-packages\django\core\handlers\base.py", line 137, in _get_response
    "returned None instead." % (callback.__module__, view_name)
ValueError: The view myweb.views.add_article didn't return an HttpResponse object. It returned None instead.
2018-08-23 01:40:28,062 [Thread-2:16128] [django.request:228] [log:log_response] [WARNING]- Not Found: /article/?
2018-08-23 01:40:28,983 [Thread-3:8984] [django.request:228] [log:log_response] [WARNING]- Not Found: /article/?
2018-08-23 01:40:29,473 [Thread-4:13668] [django.request:228] [log:log_response] [WARNING]- Not Found: /article/?
2018-08-23 01:40:29,649 [Thread-5:15260] [django.request:228] [log:log_response] [WARNING]- Not Found: /article/?
2018-08-23 01:40:30,036 [Thread-6:13572] [django.request:228] [log:log_response] [WARNING]- Not Found: /article/?
2018-08-23 01:40:30,170 [Thread-7:15660] [django.request:228] [log:log_response] [WARNING]- Not Found: /article/?
2018-08-23 01:40:32,936 [Thread-8:16036] [django.request:228] [log:log_response] [WARNING]- Not Found: /article/?
2018-08-23 01:40:43,793 [Thread-2:5356] [django.request:228] [log:log_response] [WARNING]- Not Found: /article/?
2018-08-23 01:40:44,704 [Thread-3:16988] [django.request:228] [log:log_response] [WARNING]- Not Found: /article/?
2018-08-23 01:40:44,886 [Thread-4:6956] [django.request:228] [log:log_response] [WARNING]- Not Found: /article/?
2018-08-23 01:40:47,525 [Thread-5:10160] [django.request:228] [log:log_response] [WARNING]- Not Found: /article/?
2018-08-23 01:41:44,174 [Thread-14:9652] [django.request:228] [log:log_response] [WARNING]- Not Found: /favicon.ico
2018-08-23 01:41:46,518 [Thread-15:4108] [django.request:228] [log:log_response] [ERROR]- Internal Server Error: /add_article
Traceback (most recent call last):
  File "E:\Envs\newblog-ES3JapFS\lib\site-packages\django\core\handlers\exception.py", line 34, in inner
    response = get_response(request)
  File "E:\Envs\newblog-ES3JapFS\lib\site-packages\django\core\handlers\base.py", line 137, in _get_response
    "returned None instead." % (callback.__module__, view_name)
ValueError: The view myweb.views.add_article didn't return an HttpResponse object. It returned None instead.
2018-08-23 01:41:55,106 [Thread-16:6288] [django.request:228] [log:log_response] [ERROR]- Internal Server Error: /add_article
Traceback (most recent call last):
  File "E:\Envs\newblog-ES3JapFS\lib\site-packages\django\core\handlers\exception.py", line 34, in inner
    response = get_response(request)
  File "E:\Envs\newblog-ES3JapFS\lib\site-packages\django\core\handlers\base.py", line 137, in _get_response
    "returned None instead." % (callback.__module__, view_name)
ValueError: The view myweb.views.add_article didn't return an HttpResponse object. It returned None instead.
2018-08-23 01:48:16,625 [Thread-8:17380] [django.request:228] [log:log_response] [ERROR]- Internal Server Error: /add_article
Traceback (most recent call last):
  File "E:\Envs\newblog-ES3JapFS\lib\site-packages\django\core\handlers\exception.py", line 34, in inner
    response = get_response(request)
  File "E:\Envs\newblog-ES3JapFS\lib\site-packages\django\core\handlers\base.py", line 126, in _get_response
    response = self.process_exception_by_middleware(e, request)
  File "E:\Envs\newblog-ES3JapFS\lib\site-packages\django\core\handlers\base.py", line 124, in _get_response
    response = wrapped_callback(request, *callback_args, **callback_kwargs)
  File "E:\PycharmProjects\mywebsite\myweb\views.py", line 61, in add_article
    id = request.POST.get(id)
UnboundLocalError: local variable 'id' referenced before assignment
2018-08-23 01:49:06,592 [Thread-15:16128] [django.request:228] [log:log_response] [ERROR]- Internal Server Error: /add_article
Traceback (most recent call last):
  File "E:\Envs\newblog-ES3JapFS\lib\site-packages\django\core\handlers\exception.py", line 34, in inner
    response = get_response(request)
  File "E:\Envs\newblog-ES3JapFS\lib\site-packages\django\core\handlers\base.py", line 126, in _get_response
    response = self.process_exception_by_middleware(e, request)
  File "E:\Envs\newblog-ES3JapFS\lib\site-packages\django\core\handlers\base.py", line 124, in _get_response
    response = wrapped_callback(request, *callback_args, **callback_kwargs)
  File "E:\PycharmProjects\mywebsite\myweb\views.py", line 61, in add_article
    id = request.POST.get(id)
UnboundLocalError: local variable 'id' referenced before assignment
2018-08-23 01:50:05,761 [Thread-3:6252] [django.request:228] [log:log_response] [ERROR]- Internal Server Error: /add_article
Traceback (most recent call last):
  File "E:\Envs\newblog-ES3JapFS\lib\site-packages\django\core\handlers\exception.py", line 34, in inner
    response = get_response(request)
  File "E:\Envs\newblog-ES3JapFS\lib\site-packages\django\core\handlers\base.py", line 126, in _get_response
    response = self.process_exception_by_middleware(e, request)
  File "E:\Envs\newblog-ES3JapFS\lib\site-packages\django\core\handlers\base.py", line 124, in _get_response
    response = wrapped_callback(request, *callback_args, **callback_kwargs)
  File "E:\PycharmProjects\mywebsite\myweb\views.py", line 61, in add_article
    id = request.POST.get(id)
UnboundLocalError: local variable 'id' referenced before assignment
2018-08-23 01:51:15,570 [Thread-2:10756] [django.request:228] [log:log_response] [ERROR]- Internal Server Error: /add_article
Traceback (most recent call last):
  File "E:\Envs\newblog-ES3JapFS\lib\site-packages\django\core\handlers\exception.py", line 34, in inner
    response = get_response(request)
  File "E:\Envs\newblog-ES3JapFS\lib\site-packages\django\core\handlers\base.py", line 126, in _get_response
    response = self.process_exception_by_middleware(e, request)
  File "E:\Envs\newblog-ES3JapFS\lib\site-packages\django\core\handlers\base.py", line 124, in _get_response
    response = wrapped_callback(request, *callback_args, **callback_kwargs)
  File "E:\PycharmProjects\mywebsite\myweb\views.py", line 61, in add_article
    id = request.POST.get(id)
UnboundLocalError: local variable 'id' referenced before assignment
2018-08-23 01:51:20,542 [Thread-3:14736] [django.request:228] [log:log_response] [ERROR]- Internal Server Error: /add_article
Traceback (most recent call last):
  File "E:\Envs\newblog-ES3JapFS\lib\site-packages\django\core\handlers\exception.py", line 34, in inner
    response = get_response(request)
  File "E:\Envs\newblog-ES3JapFS\lib\site-packages\django\core\handlers\base.py", line 126, in _get_response
    response = self.process_exception_by_middleware(e, request)
  File "E:\Envs\newblog-ES3JapFS\lib\site-packages\django\core\handlers\base.py", line 124, in _get_response
    response = wrapped_callback(request, *callback_args, **callback_kwargs)
  File "E:\PycharmProjects\mywebsite\myweb\views.py", line 61, in add_article
    id = request.POST.get(id)
UnboundLocalError: local variable 'id' referenced before assignment
2018-08-23 01:51:33,496 [Thread-18:6044] [django.request:228] [log:log_response] [ERROR]- Internal Server Error: /add_article
Traceback (most recent call last):
  File "E:\Envs\newblog-ES3JapFS\lib\site-packages\django\core\handlers\exception.py", line 34, in inner
    response = get_response(request)
  File "E:\Envs\newblog-ES3JapFS\lib\site-packages\django\core\handlers\base.py", line 126, in _get_response
    response = self.process_exception_by_middleware(e, request)
  File "E:\Envs\newblog-ES3JapFS\lib\site-packages\django\core\handlers\base.py", line 124, in _get_response
    response = wrapped_callback(request, *callback_args, **callback_kwargs)
  File "E:\PycharmProjects\mywebsite\myweb\views.py", line 61, in add_article
    id = request.POST.get(id)
UnboundLocalError: local variable 'id' referenced before assignment
2018-08-23 01:51:58,558 [Thread-14:17252] [django.request:228] [log:log_response] [WARNING]- Not Found: /favicon.ico
2018-08-23 01:52:08,114 [Thread-36:2020] [django.request:228] [log:log_response] [ERROR]- Internal Server Error: /add_article
Traceback (most recent call last):
  File "E:\Envs\newblog-ES3JapFS\lib\site-packages\django\core\handlers\exception.py", line 34, in inner
    response = get_response(request)
  File "E:\Envs\newblog-ES3JapFS\lib\site-packages\django\core\handlers\base.py", line 126, in _get_response
    response = self.process_exception_by_middleware(e, request)
  File "E:\Envs\newblog-ES3JapFS\lib\site-packages\django\core\handlers\base.py", line 124, in _get_response
    response = wrapped_callback(request, *callback_args, **callback_kwargs)
  File "E:\PycharmProjects\mywebsite\myweb\views.py", line 61, in add_article
    id = request.POST.get(id)
UnboundLocalError: local variable 'id' referenced before assignment
2018-08-23 01:52:29,491 [Thread-3:3916] [django.request:228] [log:log_response] [WARNING]- Not Found: /favicon.ico
2018-08-23 01:52:35,598 [Thread-3:15940] [django.request:228] [log:log_response] [WARNING]- Not Found: /favicon.ico
2018-08-23 01:53:18,977 [Thread-13:15844] [django.request:228] [log:log_response] [WARNING]- Not Found: /favicon.ico
2018-08-23 01:55:10,591 [Thread-3:12736] [django.request:228] [log:log_response] [ERROR]- Internal Server Error: /add_article
Traceback (most recent call last):
  File "E:\Envs\newblog-ES3JapFS\lib\site-packages\django\core\handlers\exception.py", line 34, in inner
    response = get_response(request)
  File "E:\Envs\newblog-ES3JapFS\lib\site-packages\django\core\handlers\base.py", line 137, in _get_response
    "returned None instead." % (callback.__module__, view_name)
ValueError: The view myweb.views.add_article didn't return an HttpResponse object. It returned None instead.
2018-08-23 01:55:38,559 [Thread-8:17388] [django.request:228] [log:log_response] [ERROR]- Internal Server Error: /add_article
Traceback (most recent call last):
  File "E:\Envs\newblog-ES3JapFS\lib\site-packages\django\core\handlers\exception.py", line 34, in inner
    response = get_response(request)
  File "E:\Envs\newblog-ES3JapFS\lib\site-packages\django\core\handlers\base.py", line 126, in _get_response
    response = self.process_exception_by_middleware(e, request)
  File "E:\Envs\newblog-ES3JapFS\lib\site-packages\django\core\handlers\base.py", line 124, in _get_response
    response = wrapped_callback(request, *callback_args, **callback_kwargs)
  File "E:\PycharmProjects\mywebsite\myweb\views.py", line 62, in add_article
    return HttpResponseRedirect('/article?id=%d'%id)
TypeError: %d format: a number is required, not NoneType
2018-08-23 01:56:05,553 [Thread-4:6840] [django.request:228] [log:log_response] [ERROR]- Internal Server Error: /add_article
Traceback (most recent call last):
  File "E:\Envs\newblog-ES3JapFS\lib\site-packages\django\core\handlers\exception.py", line 34, in inner
    response = get_response(request)
  File "E:\Envs\newblog-ES3JapFS\lib\site-packages\django\core\handlers\base.py", line 126, in _get_response
    response = self.process_exception_by_middleware(e, request)
  File "E:\Envs\newblog-ES3JapFS\lib\site-packages\django\core\handlers\base.py", line 124, in _get_response
    response = wrapped_callback(request, *callback_args, **callback_kwargs)
  File "E:\PycharmProjects\mywebsite\myweb\views.py", line 62, in add_article
    return HttpResponseRedirect('/article?id=%d'%id)
TypeError: %d format: a number is required, not NoneType
2018-08-23 01:57:38,266 [Thread-14:17208] [django.request:228] [log:log_response] [WARNING]- Not Found: /favicon.ico
2018-08-23 01:57:47,499 [Thread-36:13844] [django.request:228] [log:log_response] [ERROR]- Internal Server Error: /add_article
Traceback (most recent call last):
  File "E:\Envs\newblog-ES3JapFS\lib\site-packages\django\core\handlers\exception.py", line 34, in inner
    response = get_response(request)
  File "E:\Envs\newblog-ES3JapFS\lib\site-packages\django\core\handlers\base.py", line 126, in _get_response
    response = self.process_exception_by_middleware(e, request)
  File "E:\Envs\newblog-ES3JapFS\lib\site-packages\django\core\handlers\base.py", line 124, in _get_response
    response = wrapped_callback(request, *callback_args, **callback_kwargs)
  File "E:\PycharmProjects\mywebsite\myweb\views.py", line 62, in add_article
    return HttpResponseRedirect('/article?id=%d'%id)
TypeError: %d format: a number is required, not NoneType
2018-08-23 02:02:36,923 [Thread-14:16656] [django.request:228] [log:log_response] [WARNING]- Not Found: /favicon.ico
2018-08-23 20:21:49,227 [Thread-14:11292] [django.request:228] [log:log_response] [WARNING]- Not Found: /favicon.ico
2018-08-23 20:28:44,761 [Thread-206:16228] [django.request:228] [log:log_response] [WARNING]- Not Found: /favicon.ico
2018-08-23 20:33:10,691 [Thread-18:14616] [django.request:228] [log:log_response] [WARNING]- Not Found: /community.html
2018-08-23 20:33:19,185 [Thread-21:1916] [django.request:228] [log:log_response] [WARNING]- Not Found: /community.html
2018-08-23 20:37:56,392 [Thread-4:14160] [django.request:228] [log:log_response] [WARNING]- Not Found: /community.html
2018-08-23 20:38:09,971 [Thread-14:3020] [django.request:228] [log:log_response] [WARNING]- Not Found: /favicon.ico
2018-08-23 20:38:11,081 [Thread-15:11568] [django.request:228] [log:log_response] [WARNING]- Not Found: /community.html
2018-08-23 20:41:43,969 [Thread-16:10164] [django.request:228] [log:log_response] [WARNING]- Not Found: /community.html
2018-08-23 20:45:22,789 [Thread-45:8176] [django.request:228] [log:log_response] [WARNING]- Not Found: /community.html
2018-08-23 20:45:25,806 [Thread-47:14488] [django.request:228] [log:log_response] [WARNING]- Not Found: /community.html
2018-08-23 20:45:45,529 [Thread-65:4268] [django.request:228] [log:log_response] [WARNING]- Not Found: /community.html
2018-08-23 20:49:00,014 [Thread-6:12704] [django.request:228] [log:log_response] [WARNING]- Not Found: /community.html
2018-08-23 21:01:23,498 [Thread-3:11900] [django.request:228] [log:log_response] [WARNING]- Not Found: /@Url.Action('home','community',new{area='add_article')
2018-08-23 21:09:29,012 [Thread-15:9496] [django.request:228] [log:log_response] [WARNING]- Not Found: /community.html
2018-08-23 21:10:17,836 [Thread-37:4476] [django.request:228] [log:log_response] [WARNING]- Not Found: /blog/add_article/
2018-08-23 21:10:22,966 [Thread-42:12092] [django.request:228] [log:log_response] [WARNING]- Not Found: /favicon.ico
2018-08-23 21:10:22,974 [Thread-43:15944] [django.request:228] [log:log_response] [WARNING]- Not Found: /favicon.ico
2018-08-23 21:13:29,187 [Thread-85:9352] [django.request:228] [log:log_response] [WARNING]- Not Found: /favicon.ico
2018-08-23 21:35:47,724 [Thread-14:15204] [django.request:228] [log:log_response] [WARNING]- Not Found: /favicon.ico
2018-08-23 21:47:52,232 [Thread-4:16208] [django.request:228] [log:log_response] [WARNING]- Not Found: /favicon.ico
2018-08-23 21:48:20,251 [Thread-15:10360] [django.request:228] [log:log_response] [WARNING]- Not Found: /favicon.ico
2018-08-23 21:49:54,502 [Thread-115:1460] [django.request:228] [log:log_response] [WARNING]- Not Found: /blog/add_article/
2018-08-23 21:49:57,228 [Thread-120:8464] [django.request:228] [log:log_response] [WARNING]- Not Found: /favicon.ico
2018-08-23 21:49:57,360 [Thread-121:9652] [django.request:228] [log:log_response] [WARNING]- Not Found: /favicon.ico
2018-08-23 22:06:24,101 [Thread-14:14580] [django.request:228] [log:log_response] [WARNING]- Not Found: /favicon.ico
2018-08-23 22:10:27,026 [Thread-12:13548] [django.request:228] [log:log_response] [WARNING]- Not Found: /favicon.ico
2018-08-23 22:10:32,644 [Thread-26:11096] [django.request:228] [log:log_response] [WARNING]- Not Found: /favicon.ico
2018-08-23 22:11:39,862 [Thread-28:7936] [django.request:228] [log:log_response] [WARNING]- Not Found: /favicon.ico
2018-08-23 22:11:47,287 [Thread-45:13216] [django.request:228] [log:log_response] [WARNING]- Not Found: /favicon.ico
2018-08-23 22:13:00,274 [Thread-47:10304] [django.request:228] [log:log_response] [WARNING]- Not Found: /favicon.ico
2018-08-23 22:14:00,303 [Thread-62:10192] [django.request:228] [log:log_response] [WARNING]- Not Found: /favicon.ico
2018-08-23 22:17:32,625 [Thread-14:12216] [django.request:228] [log:log_response] [WARNING]- Not Found: /favicon.ico
2018-08-23 23:33:10,310 [Thread-14:11488] [django.request:228] [log:log_response] [WARNING]- Not Found: /favicon.ico
2018-08-24 00:45:44,589 [Thread-14:10268] [django.request:228] [log:log_response] [WARNING]- Not Found: /favicon.ico
